<?xml version='1.0'?>

<robot name="yemenbot" xmlns:xacro="http://www.ros.org/wiki/xacro">

  <xacro:property name="cameraSize" value="0.05"/>
  <xacro:property name="cameraMass" value="0.1"/>
 <xacro:property  name="cam_px" value="0.25"/>
  <xacro:property name="cam_py" value="0"/>
  <xacro:property name="cam_pz" value="0.23" />
   <xacro:property name="cam_or" value="0" />
  <xacro:property name="cam_op" value="0"/>
  <xacro:property name="cam_oy" value="0"/>
  <xacro:property name="M_PI" value="3.14" />
  
  <xacro:include filename="$(find yemenbot)/urdf/yemenbot.gazebo" />
  <xacro:include filename="$(find yemenbot)/urdf/materials.xacro" />
  <xacro:include filename="$(find yemenbot)/urdf/macros.xacro" />


    <!--link name='chassis'>
    <pose>0 0 0.1 0 0 0</pose>

    <inertial>
      <mass value="15.0"/>
      <origin xyz="0.0 0 0.1" rpy=" 0 0 0"/>
      <inertia
          ixx="0.1" ixy="0" ixz="0"
          iyy="0.1" iyz="0"
          izz="0.1"
      />
    </inertial>

    <collision name='collision'>
      <geometry>
        <box size=".4 .2 .1"/>
      </geometry>
    </collision>

    <visual name='chassis_visual'>
      <origin xyz="0 0 0" rpy=" 0 0 0"/>
      <geometry>
        <box size=".4 .2 .1"/>
      </geometry>
    </visual>


    <collision name='caster_collision'>
      <origin xyz="-0.15 0 -0.05" rpy=" 0 0 0"/>
      <geometry>
        <sphere radius="0.05"/>
      </geometry>
      <surface>
        <friction>
          <ode>
            <mu>0</mu>
            <mu2>0</mu2>
            <slip1>1.0</slip1>
            <slip2>1.0</slip2>
          </ode>
        </friction>
      </surface>
    </collision>

    <visual name='caster_visual'>
      <origin xyz="-0.15 0 -0.05" rpy=" 0 0 0"/>
      <geometry>
        <sphere radius="0.05"/>
      </geometry>
    </visual>

    <collision name='caster_front_collision'>
      <origin xyz="0.15 0 -0.05" rpy=" 0 0 0"/>
      <geometry>
        <sphere radius="0.05"/>
      </geometry>
      <surface>
        <friction>
          <ode>
            <mu>0</mu>
            <mu2>0</mu2>
            <slip1>1.0</slip1>
            <slip2>1.0</slip2>
          </ode>
        </friction>
      </surface>
    </collision>

    <visual name='caster_front_visual'>
      <origin xyz="0.15 0 -0.05" rpy=" 0 0 0"/>
      <geometry>
        <sphere radius="0.05"/>
      </geometry>
    </visual>

  </link-->
  
  
  
  
  <link name='chassis'>
    <pose>0 0 0.06 0 0 0</pose>

    <inertial>
      <mass value="5.0"/>
      <origin xyz="0.0 0 0.06" rpy=" 0 0 0"/>
      <inertia
          ixx="0.04" ixy="0" ixz="0"
          iyy="0.1" iyz="0"
          izz="0.1"
      />
    </inertial>

    <collision name='collision'>
      <geometry>
        <box size=".45 .3 .01"/>
      </geometry>
    </collision>

    <visual name='chassis_visual'>
      <origin xyz="0 0 0" rpy=" 0 0 0"/>
      <geometry>
        <box size=".45 .3 .01"/>
      </geometry>
      <material name="black"/>
    </visual>

    <collision name='caster_collision'>
      <origin xyz="0.15 0 -0.025" rpy=" 0 0 0"/>
      <geometry>
        <sphere radius="0.025"/>
      </geometry>
      <surface>
        <friction>
          <ode>
            <mu>0</mu>
            <mu2>0</mu2>
            <slip1>1.0</slip1>
            <slip2>1.0</slip2>
          </ode>
        </friction>
      </surface>
    </collision>

    <visual name='caster_visual'>
      <origin xyz="0.15 0 -0.025" rpy=" 0 0 0"/>
      <geometry>
        <sphere radius="0.025"/>
      </geometry>
      <material name="white"/>
    </visual>
    
    
    <collision name='colume1_collision'>
      <origin xyz="0.06 -0.135 0.1" rpy=" 0 0 0"/>
      <geometry>
        <cylinder radius="0.008" length="0.225"/>
      </geometry>
    </collision>

    <visual name='colume1_visual'>
      <origin xyz="0.06 -0.135 0.1" rpy=" 0 0 0"/>
      <geometry>
        <cylinder radius="0.008" length="0.225"/>
      </geometry>
      <material name="white"/>
    </visual>
    
    
    
      <collision name='colume2_collision'>
      <origin xyz="0.06 0.135 0.1" rpy=" 0 0 0"/>
      <geometry>
        <cylinder radius="0.008" length="0.225"/>
      </geometry>
    </collision>

    <visual name='colume2_visual'>
      <origin xyz="0.06 0.135 0.1" rpy=" 0 0 0"/>
      <geometry>
        <cylinder radius="0.008" length="0.225"/>
      </geometry>
      <material name="white"/>
    </visual>
    
    
    
      <collision name='colume3_collision'>
      <origin xyz="-0.21 0.135 0.1" rpy=" 0 0 0"/>
      <geometry>
        <cylinder radius="0.008" length="0.225"/>
      </geometry>
    </collision>

    <visual name='colume3_visual'>
      <origin xyz="-0.21 0.135 0.1" rpy=" 0 0 0"/>
      <geometry>
        <cylinder radius="0.008" length="0.225"/>
      </geometry>
      <material name="white"/>
    </visual>
    
    
    
    
      <collision name='colume4_collision'>
      <origin xyz="-0.21 -0.135 0.1" rpy=" 0 0 0"/>
      <geometry>
        <cylinder radius="0.008" length="0.225"/>
      </geometry>
    </collision>

    <visual name='colume4_visual'>
      <origin xyz="-0.21 -0.135 0.1" rpy=" 0 0 0"/>
      <geometry>
        <cylinder radius="0.008" length="0.225"/>
      </geometry>
      <material name="white"/>
    </visual>

  </link>
  
  
   <joint name="middle_link_joint" type="fixed">
      <origin xyz="-0.075 0 0.1" rpy="0 0 0"/>
      <parent link="chassis"/>
      <child link="middle_link" />
    </joint>
  
  <link name='middle_link'>
    <inertial>
      <mass value="5.0"/>
      <origin xyz="0.0 0 0.0" rpy=" 0 0 0"/>
      <inertia
          ixx="0.04" ixy="0" ixz="0"
          iyy="0.1" iyz="0"
          izz="0.1"
      />
    </inertial>

    <collision name='middle_link_collision'>
    <origin xyz="0 0 0" rpy=" 0 0 0"/>
      <geometry>
        <box size=".30 .3 .01"/>
      </geometry>
    </collision>

    <visual name='middle_link_visual'>
      <origin xyz="0 0 0" rpy=" 0 0 0"/>
      <geometry>
        <box size=".30 .3 .01"/>
      </geometry>
      <material name="white"/>
    </visual>
  </link>
  
  
  <joint name="up_link_joint" type="fixed">
      <origin xyz="0 0 0.2" rpy="0 0 0"/>
      <parent link="chassis"/>
      <child link="up_link" />
    </joint>
  
  <link name='up_link'>
    <inertial>
      <mass value="5.0"/>
      <origin xyz="0.0 0 0.0" rpy="0 0 0"/>
      <inertia
          ixx="0.04" ixy="0" ixz="0"
          iyy="0.1" iyz="0"
          izz="0.1"
      />
    </inertial>

    <collision name='up_link_collision'>
    <origin xyz="0 0 0" rpy=" 0 0 0"/>
      <geometry>
        <box size=".45 .3 .01"/>
      </geometry>
    </collision>

    <visual name='up_link_visual'>
      <origin xyz="0 0 0" rpy=" 0 0 0"/>
      <geometry>
        <box size=".45 .3 .01"/>
      </geometry>
      <material name="red"/>
    </visual>
  </link>
  
  
   <joint name="camera_rgb_joint" type="fixed">
      <origin xyz="${cam_px} ${cam_py} ${cam_pz}" rpy="${cam_or} ${cam_op} ${cam_oy}"/>
      <parent link="chassis"/>
      <child link="camera_rgb_frame" />
    </joint>
    <link name="camera_rgb_frame">
      <inertial>
        <mass value="0.001" />
        <origin xyz="0 0 0" />
        <inertia ixx="0.0001" ixy="0.0" ixz="0.0"
                 iyy="0.0001" iyz="0.0"
                 izz="0.0001" />
      </inertial>
    </link>
    <joint name="camera_rgb_optical_joint" type="fixed">
      <origin xyz="0 0 0" rpy="${-M_PI/2} 0 ${-M_PI/2}" />
      <parent link="camera_rgb_frame" />
      <child link="camera_rgb_optical_frame" />
    </joint>
    <link name="camera_rgb_optical_frame">
      <inertial>
        <mass value="0.001" />
        <origin xyz="0 0 0" />
        <inertia ixx="0.0001" ixy="0.0" ixz="0.0"
                 iyy="0.0001" iyz="0.0"
                 izz="0.0001" />
      </inertial>
    </link>

  <joint name="camera_joint" type="fixed">
    <origin xyz="-0.031 ${-cam_py} -0.016" rpy="0 0 0"/>
    <parent link="camera_rgb_frame"/>
    <child link="camera_link"/>
  </joint>  
    <link name="camera_link">
    <visual>
     <origin xyz="0 0 0" rpy="0 0 0"/>
      <geometry>
       <mesh filename="package://yemenbot/meshes/kinect.dae"/>
      </geometry>
    </visual>
	  <collision>
      <origin xyz="0.0 0.0 0.0" rpy="0 0 0"/>
	    <geometry>
	      <box size="0.07271 0.27794 0.073"/>
	    </geometry>
	  </collision>
    <inertial>
      <mass value="0.001" />
      <origin xyz="0 0 0" />
      <inertia ixx="0.0001" ixy="0.0" ixz="0.0"
               iyy="0.0001" iyz="0.0"
               izz="0.0001" />
    </inertial>
  </link>
	  
  <!-- The fixed joints & links below are usually published by static_transformers launched by the OpenNi launch 
       files. However, for Gazebo simulation we need them, so we add them here.
       (Hence, don't publish them additionally!) -->
	<joint name="camera_depth_joint" type="fixed">
	  <origin xyz="0 ${2 * -cam_py} 0" rpy="0 0 0" />
	  <parent link="camera_rgb_frame" />
	  <child link="camera_depth_frame" />
	</joint>
	<link name="camera_depth_frame">
    <inertial>
      <mass value="0.001" />
      <origin xyz="0 0 0" />
      <inertia ixx="0.0001" ixy="0.0" ixz="0.0"
               iyy="0.0001" iyz="0.0"
               izz="0.0001" />
    </inertial>
	</link>
	<joint name="camera_depth_optical_joint" type="fixed">
	  <origin xyz="0 0 0" rpy="${-M_PI/2} 0 ${-M_PI/2}" />
	  <parent link="camera_depth_frame" />
	  <child link="camera_depth_optical_frame" />
	</joint>
	<link name="camera_depth_optical_frame">
    <inertial>
      <mass value="0.001" />
      <origin xyz="0 0 0" />
      <inertia ixx="0.0001" ixy="0.0" ixz="0.0"
               iyy="0.0001" iyz="0.0"
               izz="0.0001" />
    </inertial>
	</link>


  <link name="left_wheel">
    <!--origin xyz="0.1 0.13 0.1" rpy="0 1.5707 1.5707"/-->
    <collision name="collision">
      <origin xyz="0 0 0" rpy="0 1.5707 1.5707"/>
      <geometry>
        <cylinder radius="0.04" length="0.05"/>
      </geometry>
    </collision>
    <visual name="left_wheel_visual">
      <origin xyz="0 0 0" rpy="0 1.5707 1.5707"/>
      <geometry>
        <cylinder radius="0.04" length="0.05"/>
      </geometry>
       <material name="blue"/>
    </visual>
    <inertial>
      <origin xyz="0 0 0" rpy="0 1.5707 1.5707"/>
      <mass value="5"/>
      <inertia
        ixx=".1" ixy="0.0" ixz="0.0"
        iyy=".1" iyz="0.0"
        izz=".1"/>
    </inertial>
  </link>

  <link name="right_wheel">
    <!--origin xyz="0.1 -0.13 0.1" rpy="0 1.5707 1.5707"/-->
    <collision name="collision">
      <origin xyz="0 0 0" rpy="0 1.5707 1.5707"/>
      <geometry>
        <cylinder radius="0.04" length="0.05"/>
      </geometry>
    </collision>
    <visual name="right_wheel_visual">
      <origin xyz="0 0 0" rpy="0 1.5707 1.5707"/>
      <geometry>
        <cylinder radius="0.04" length="0.05"/>
      </geometry>
       <material name="blue"/>
    </visual>
    <inertial>
      <origin xyz="0 0 0" rpy="0 1.5707 1.5707"/>
      <mass value="5"/>
      <inertia
        ixx=".1" ixy="0.0" ixz="0.0"
        iyy=".1" iyz="0.0"
        izz=".1"/>
    </inertial>
  </link>


  <joint type="continuous" name="left_wheel_hinge">
    <!--origin xyz="0 0.15 0" rpy="0 0 0"/-->
    <origin xyz="-0.15 0.13 0" rpy="0 0 0"/>
    <child link="left_wheel"/>
    <parent link="chassis"/>
    <axis xyz="0 1 0" rpy="0 0 0"/>
    <limit effort="10000" velocity="1000"/>
    <joint_properties damping="1.0" friction="1.0"/>
  </joint>

  <joint type="continuous" name="right_wheel_hinge">
    <!--origin xyz="0 -0.15 0" rpy="0 0 0"/-->
    <origin xyz="-0.15 -0.13 0" rpy="0 0 0"/>
    <child link="right_wheel"/>
    <parent link="chassis"/>
    <axis xyz="0 1 0" rpy="0 0 0"/>
    <limit effort="10000" velocity="1000"/>
    <joint_properties damping="1.0" friction="1.0"/>
  </joint>
</robot>
